fix bug:

Traceback (most recent call last):
  File "/Users/mac/Desktop/gpt_test/mycode/main.py", line 16, in <module>
    main()
  File "/Users/mac/Desktop/gpt_test/mycode/main.py", line 13, in main
    file_reader.traverse_and_write(output_file)
  File "/Users/mac/Desktop/gpt_test/mycode/file_reader.py", line 27, in traverse_and_write
    with open(file_path, 'r') as f:
              ^^^^^^^^^
UnboundLocalError: cannot access local variable 'file_path' where it is not associated with a value